<?xml version="1.0"?>
<robot xmlns:xacro="http://ros.org/wiki/xacro">

  <joint name="${prefix}wheel_left_joint" type="continuous">
    <parent link="${prefix}base_link"/>
    <child link="${prefix}wheel_left"/>
    <origin xyz="-0.1 0.1 -0.05" rpy="0 0 0"/>
    <axis xyz="0 1 0"/>
  </joint>

  <joint name="${prefix}wheel_right_joint" type="continuous">
    <parent link="${prefix}base_link"/>
    <child link="${prefix}wheel_right"/>
    <origin xyz="-0.1 -0.1 -0.05" rpy="0 0 0"/>
    <axis xyz="0 1 0"/>
  </joint>

</robot>
